<?xml version="1.0"?>
<robot xmlns:xacro="http://www.ros.org/wiki/xacro">

    <xacro:include filename="inertial_macros.xacro" />

    <!-- 颜色定义 -->
    <material name="white">
        <color rgba="1 1 1 1" />
    </material>

    <material name="orange">
        <color rgba="1 0.3 0.1 1" />
    </material>

    <material name="blue">
        <color rgba="0.2 0.2 1 1" />
    </material>

    <material name="black">
        <color rgba="0 0 0 1" />
    </material>

    <material name="red">
        <color rgba="1 0 0 1" />
    </material>

    <link name="base_link">

    </link>

    <!-- BASE_FOOTPRINT -->

    <joint name="base_footprint_joint" type="fixed">
        <parent link="base_footprint" />
        <child link="base_link" />
        <origin xyz="0 0 0.05" rpy="0 0 0" />
    </joint>

    <link name="base_footprint">
    </link>

    <!-- 车身结构 -->

    <joint name="chassis_joint" type="fixed">
        <parent link="base_link" />
        <child link="chassis" />
        <origin xyz="0 0 0" />
    </joint>

    <link name="chassis">
        <visual>
            <origin xyz="0.0 0 0.075" rpy="0 0 0" />
            <geometry>
                <box size="0.3 0.3 0.15" />
            </geometry>
            <material name="white" />
        </visual>
        <collision>
            <origin xyz="0.0 0.0 0.075" rpy="0.0 0.0 0.0" />
            <geometry>
                <box size="0.3 0.3 0.15" />
            </geometry>
        </collision>
        <xacro:inertial_box mass="3.5" x="0.3" y="0.3" z="0.15">
            <origin xyz="0.0 0 0.075" rpy="0 0 0" />
        </xacro:inertial_box>
    </link>

    <joint name="left_wheel_joint" type="continuous">
        <parent link="base_link" />
        <child link="left_wheel" />
        <origin xyz="0.0 0.175 0.0" rpy="-${pi/2} 0.0 0.0" />
        <axis xyz="0.0 0.0 1.0" />

        <limit effort="100.0" velocity="10.0" />

        <dynamics damping="0.2" friction="0.2" />
    </joint>

    <link name="left_wheel">
        <visual>
            <geometry>
                <cylinder radius="0.05" length="0.04" />
            </geometry>
            <material name="blue" />
        </visual>

        <collision>
            <geometry>
                <sphere radius="0.05" />
            </geometry>
        </collision>

        <xacro:inertial_cylinder mass="0.25" length="0.04" radius="0.05">
            <origin xyz="0 0 0" rpy="0 0 0" />
        </xacro:inertial_cylinder>
    </link>

    <gazebo reference="left_wheel">
        <mu1>1.0</mu1>
        <mu2>0.5</mu2>
        <kp>500000.0</kp>
        <kd>10.0</kd>
        <minDepth>0.001</minDepth>
        <maxVel>0.1</maxVel>
        <fdir1>1 0 0</fdir1>
        <material>Gazebo/Blue</material>
    </gazebo>

    <joint name="right_wheel_joint" type="continuous">
        <parent link="base_link" />
        <child link="right_wheel" />
        <origin xyz="0.0 -0.175 0.0" rpy="${pi/2} 0.0 0.0" />
        <axis xyz="0.0 0.0 -1.0" />

        <limit effort="100.0" velocity="10.0" />
        <dynamics damping="0.2" friction="0.2" />
    </joint>

    <link name="right_wheel">
        <visual>
            <geometry>
                <cylinder radius="0.05" length="0.04" />
            </geometry>
            <material name="blue" />
        </visual>

        <collision>
            <geometry>
                <sphere radius="0.05" />
            </geometry>
        </collision>

        <xacro:inertial_cylinder mass="0.25" length="0.04" radius="0.05">
            <origin xyz="0 0 0" rpy="0 0 0" />
        </xacro:inertial_cylinder>
    </link>

    <gazebo reference="right_wheel">
        <mu1>100000.0</mu1>
        <mu2>100000.0</mu2>
        <kp>1000000.0</kp>
        <kd>100.0</kd>
        <minDepth>0.001</minDepth>
        <maxVel>0.1</maxVel>
        <fdir1>1 0 0</fdir1>
        <material>Gazebo/Blue</material>
    </gazebo>

    <!-- 前辅助轮 -->
    <joint name="caster_front_joint" type="fixed">
        <parent link="chassis" />
        <child link="caster_front_wheel" />
        <origin xyz="0.12 0 0" rpy="0 0 0" />
    </joint>

    <link name="caster_front_wheel">
        <visual>
            <geometry>
                <sphere radius="0.05" />
            </geometry>
            <material name="black" />
        </visual>
        <collision>
            <geometry>
                <sphere radius="0.05" />
            </geometry>
        </collision>
        <xacro:inertial_sphere mass="0.1" radius="0.05">
            <origin xyz="0 0 0" rpy="0 0 0" />
        </xacro:inertial_sphere>
    </link>

    <gazebo reference="caster_front_wheel">
        <mu1>0.0001</mu1>
        <mu2>0.0001</mu2>
        <kp>1000000.0</kp>
        <kd>100.0</kd>
        <minDepth>0.001</minDepth>
        <maxVel>1.0</maxVel>
        <material>Gazebo/Black</material>
    </gazebo>

    <!-- 后辅助轮 -->
    <joint name="caster_back_joint" type="fixed">
        <parent link="chassis" />
        <child link="caster_back_wheel" />
        <origin xyz="-0.12 0 0" rpy="0 0 0" />   <!-- 后方对称位置 -->
    </joint>

    <link name="caster_back_wheel">
        <visual>
            <geometry>
                <sphere radius="0.05" />
            </geometry>
            <material name="black" />
        </visual>
        <collision>
            <geometry>
                <sphere radius="0.05" />
            </geometry>
        </collision>
        <xacro:inertial_sphere mass="0.1" radius="0.05">
            <origin xyz="0 0 0" rpy="0 0 0" />
        </xacro:inertial_sphere>
    </link>

    <gazebo reference="caster_back_wheel">
        <mu1>0.0001</mu1>
        <mu2>0.0001</mu2>
        <kp>1000000.0</kp>
        <kd>100.0</kd>
        <minDepth>0.001</minDepth>
        <maxVel>1.0</maxVel>
        <material>Gazebo/Black</material>
    </gazebo>

</robot>